Workbook

Sheet Introduction

Sheet RAD Data
A1: Sol | B1: 24h averaged RAD Temp interpolated [K] | C1: Variation of 24h average Rad Temp [K] | D1: Minimum RAD Temp interpolated [K] | E1: Maximum RAD Temp interpolated [K] | F1: Average of Max/Min RAD Temp (C+D)/2 [K] | G1: Variation of Av of Max/Min | H1: F-B [K] | I1: H-$K$2 [K] | J1: Scaled variation of average of Max/Min
A2: 20 | B2: 222.41174 | C2: =B2-$K$4 -> 0.042706315 | D2: 183.957 | E2: 285.12 | F2: =(D2+E2)/2 -> 234.5385 | G2: =F2-$K$3 -> 1.6338201 | H2: =F2-B2 -> 12.126764 | I2: =(H2-$K$2) -> 1.5911138 | J2: =G2/($K$8-$K$3) -> 0.19910504 | K2: =AVERAGE(H2:H1227) -> 10.53565
A3: 21 | B3: 222.70496 | C3: =B3-$K$4 -> 0.33593517 | D3: 184.662 | E3: 284.907 | F3: =(D3+E3)/2 -> 234.7845 | G3: =F3-$K$3 -> 1.8798201 | H3: =F3-B3 -> 12.079535 | I3: =(H3-$K$2) -> 1.543885 | J3: =G3/($K$8-$K$3) -> 0.22908376 | K3: =AVERAGE(F2:F1227) -> 232.90468
A4: 22 | B4: 222.99819 | C4: =B4-$K$4 -> 0.62916403 | D4: 185.368 | E4: 284.694 | F4: =(D4+E4)/2 -> 235.031 | G4: =F4-$K$3 -> 2.1263201 | H4: =F4-B4 -> 12.032807 | I4: =(H4-$K$2) -> 1.4971561 | J4: =G4/($K$8-$K$3) -> 0.25912342 | K4: =AVERAGE(B2:B1227) -> 222.36903
A5: 23 | B5: 223.29142 | C5: =B5-$K$4 -> 0.92239289 | D5: 186.073 | E5: 284.78 | F5: =(D5+E5)/2 -> 235.4265 | G5: =F5-$K$3 -> 2.5218201 | H5: =F5-B5 -> 12.135078 | I5: =(H5-$K$2) -> 1.5994273 | J5: =G5/($K$8-$K$3) -> 0.30732091 | K5: Min Max
A6: 24 | B6: 223.58465 | C6: =B6-$K$4 -> 1.2156218 | D6: 186.778 | E6: 284.78 | F6: =(D6+E6)/2 -> 235.779 | G6: =F6-$K$3 -> 2.8743201 | H6: =F6-B6 -> 12.194349 | I6: =(H6-$K$2) -> 1.6586984 | J6: =G6/($K$8-$K$3) -> 0.35027823 | K6: =MIN(C2:C12227) -> -6.847205
A7: 25 | B7: 223.59576 | C7: =B7-$K$4 -> 1.2267341 | D7: 186.778 | E7: 284.78 | F7: =(D7+E7)/2 -> 235.779 | G7: =F7-$K$3 -> 2.8743201 | H7: =F7-B7 -> 12.183236 | I7: =(H7-$K$2) -> 1.6475861 | J7: =G7/($K$8-$K$3) -> 0.35027823 | K7: =MAX(C2:C1227) -> 7.04928
A8: 26 | B8: 223.64922 | C8: =B8-$K$4 -> 1.2801878 | D8: 186.72 | E8: 284.894 | F8: =(D8+E8)/2 -> 235.807 | G8: =F8-$K$3 -> 2.9023201 | H8: =F8-B8 -> 12.157783 | I8: =(H8-$K$2) -> 1.6221324 | J8: =G8/($K$8-$K$3) -> 0.35369044 | K8: =MAX(F2:F1227) -> 241.1105
A9: 27 | B9: 223.70267 | C9: =B9-$K$4 -> 1.3336415 | D9: 186.662 | E9: 285.008 | F9: =(D9+E9)/2 -> 235.835 | G9: =F9-$K$3 -> 2.9303201 | H9: =F9-B9 -> 12.132329 | I9: =(H9-$K$2) -> 1.5966787 | J9: =G9/($K$8-$K$3) -> 0.35710265
A10: 28 | B10: 223.64893 | C10: =B10-$K$4 -> 1.2798985 | D10: 186.775 | E10: 285.008 | F10: =(D10+E10)/2 -> 235.8915 | G10: =F10-$K$3 -> 2.9868201 | H10: =F10-B10 -> 12.242572 | I10: =(H10-$K$2) -> 1.7069217 | J10: =G10/($K$8-$K$3) -> 0.36398801 | K10: Max 13h
A11: 29 | B11: 223.60163 | C11: =B11-$K$4 -> 1.232601 | D11: 186.327 | E11: 285.008 | F11: =(D11+E11)/2 -> 235.6675 | G11: =F11-$K$3 -> 2.7628201 | H11: =F11-B11 -> 12.06587 | I11: =(H11-$K$2) -> 1.5302192 | J11: =G11/($K$8-$K$3) -> 0.33669031 | K11: =MAX(E663:E1227) -> 291.812
A12: 30 | B12: 223.9169 | C12: =B12-$K$4 -> 1.547875 | D12: 186.309 | E12: 285.595 | F12: =(D12+E12)/2 -> 235.952 | G12: =F12-$K$3 -> 3.0473201 | H12: =F12-B12 -> 12.035096 | I12: =(H12-$K$2) -> 1.4994452 | J12: =G12/($K$8-$K$3) -> 0.37136083 | K12: =MIN(E663:E1227) -> 266.728
A13: 31 | B13: 224.23218 | C13: =B13-$K$4 -> 1.863149 | D13: 185.886 | E13: 286.415 | F13: =(D13+E13)/2 -> 236.1505 | G13: =F13-$K$3 -> 3.2458201 | H13: =F13-B13 -> 11.918322 | I13: =(H13-$K$2) -> 1.3826712 | J13: =G13/($K$8-$K$3) -> 0.39555097 | K13: =K11-K12 -> 25.084
A14: 32 | B14: 223.91399 | C14: =B14-$K$4 -> 1.5449597 | D14: 186.635 | E14: 286.415 | F14: =(D14+E14)/2 -> 236.525 | G14: =F14-$K$3 -> 3.6203201 | H14: =F14-B14 -> 12.611011 | I14: =(H14-$K$2) -> 2.0753605 | J14: =G14/($K$8-$K$3) -> 0.44118931 | K14: Range
A15: 33 | B15: 224.09135 | C15: =B15-$K$4 -> 1.7223169 | D15: 186.573 | E15: 284.919 | F15: =(D15+E15)/2 -> 235.746 | G15: =F15-$K$3 -> 2.8413201 | H15: =F15-B15 -> 11.654654 | I15: =(H15-$K$2) -> 1.1190032 | J15: =G15/($K$8-$K$3) -> 0.34625669 | K15: =K7-K6 -> 13.896485
A16: 34 | B16: 223.99499 | C16: =B16-$K$4 -> 1.6259631 | D16: 186.529 | E16: 286.015 | F16: =(D16+E16)/2 -> 236.272 | G16: =F16-$K$3 -> 3.3673201 | H16: =F16-B16 -> 12.277007 | I16: =(H16-$K$2) -> 1.741357 | J16: =G16/($K$8-$K$3) -> 0.41035754 | K16: Period
A17: 35 | B17: 224.11977 | C17: =B17-$K$4 -> 1.7507396 | D17: 186.765 | E17: 285.634 | F17: =(D17+E17)/2 -> 236.1995 | G17: =F17-$K$3 -> 3.2948201 | H17: =F17-B17 -> 12.079731 | I17: =(H17-$K$2) -> 1.5440806 | J17: =G17/($K$8-$K$3) -> 0.40152234 | K17: =A1227-A2 -> 1225
A18: 36 | B18: 224.22037 | C18: =B18-$K$4 -> 1.8513451 | D18: 186.255 | E18: 285.911 | F18: =(D18+E18)/2 -> 236.083 | G18: =F18-$K$3 -> 3.1783201 | H18: =F18-B18 -> 11.862625 | I18: =(H18-$K$2) -> 1.3269751 | J18: =G18/($K$8-$K$3) -> 0.3873251
A19: 37 | B19: 224.07638 | C19: =B19-$K$4 -> 1.7073499 | D19: 187.3 | E19: 285.368 | F19: =(D19+E19)/2 -> 236.334 | G19: =F19-$K$3 -> 3.4293201 | H19: =F19-B19 -> 12.257621 | I19: =(H19-$K$2) -> 1.7219703 | J19: =G19/($K$8-$K$3) -> 0.41791315
A20: 38 | B20: 224.0109 | C20: =B20-$K$4 -> 1.6418731 | D20: 187.039 | E20: 284.825 | F20: =(D20+E20)/2 -> 235.932 | G20: =F20-$K$3 -> 3.0273201 | H20: =F20-B20 -> 11.921097 | I20: =(H20-$K$2) -> 1.3854471 | J20: =G20/($K$8-$K$3) -> 0.36892353
A21: 39 | B21: 224.19618 | C21: =B21-$K$4 -> 1.8271547 | D21: 187.414 | E21: 285.194 | F21: =(D21+E21)/2 -> 236.304 | G21: =F21-$K$3 -> 3.3993201 | H21: =F21-B21 -> 12.107816 | I21: =(H21-$K$2) -> 1.5721654 | J21: =G21/($K$8-$K$3) -> 0.41425721
A22: 40 | B22: 224.60137 | C22: =B22-$K$4 -> 2.2323405 | D22: 187.535 | E22: 285.564 | F22: =(D22+E22)/2 -> 236.5495 | G22: =F22-$K$3 -> 3.6448201 | H22: =F22-B22 -> 11.94813 | I22: =(H22-$K$2) -> 1.4124797 | J22: =G22/($K$8-$K$3) -> 0.444175
A23: 41 | B23: 224.68273 | C23: =B23-$K$4 -> 2.3136974 | D23: 187.655 | E23: 285.778 | F23: =(D23+E23)/2 -> 236.7165 | G23: =F23-$K$3 -> 3.8118201 | H23: =F23-B23 -> 12.033773 | I23: =(H23-$K$2) -> 1.4981228 | J23: =G23/($K$8-$K$3) -> 0.46452641
A24: 42 | B24: 224.58591 | C24: =B24-$K$4 -> 2.2168847 | D24: 187.833 | E24: 285.453 | F24: =(D24+E24)/2 -> 236.643 | G24: =F24-$K$3 -> 3.7383201 | H24: =F24-B24 -> 12.057086 | I24: =(H24-$K$2) -> 1.5214354 | J24: =G24/($K$8-$K$3) -> 0.45556935
A25: 43 | B25: 224.32552 | C25: =B25-$K$4 -> 1.9564888 | D25: 188.186 | E25: 284.462 | F25: =(D25+E25)/2 -> 236.324 | G25: =F25-$K$3 -> 3.4193201 | H25: =F25-B25 -> 11.998482 | I25: =(H25-$K$2) -> 1.4628313 | J25: =G25/($K$8-$K$3) -> 0.4166945
A26: 44 | B26: 224.16115 | C26: =B26-$K$4 -> 1.7921214 | D26: 189.247 | E26: 282.543 | F26: =(D26+E26)/2 -> 235.895 | G26: =F26-$K$3 -> 2.9903201 | H26: =F26-B26 -> 11.733849 | I26: =(H26-$K$2) -> 1.1981988 | J26: =G26/($K$8-$K$3) -> 0.36441454
A27: 45 | B27: 223.70685 | C27: =B27-$K$4 -> 1.3378255 | D27: 189.247 | E27: 282.036 | F27: =(D27+E27)/2 -> 235.6415 | G27: =F27-$K$3 -> 2.7368201 | H27: =F27-B27 -> 11.934645 | I27: =(H27-$K$2) -> 1.3989947 | J27: =G27/($K$8-$K$3) -> 0.33352183
A28: 46 | B28: 224.02339 | C28: =B28-$K$4 -> 1.6543604 | D28: 190.147 | E28: 281.529 | F28: =(D28+E28)/2 -> 235.838 | G28: =F28-$K$3 -> 2.9333201 | H28: =F28-B28 -> 11.81461 | I28: =(H28-$K$2) -> 1.2789597 | J28: =G28/($K$8-$K$3) -> 0.35746825
A29: 47 | B29: 223.79081 | C29: =B29-$K$4 -> 1.4217788 | D29: 190.147 | E29: 281.954 | F29: =(D29+E29)/2 -> 236.0505 | G29: =F29-$K$3 -> 3.1458201 | H29: =F29-B29 -> 12.259692 | I29: =(H29-$K$2) -> 1.7240414 | J29: =G29/($K$8-$K$3) -> 0.3833645
... A96: 114 | B96: 224.09418 | C96: =B96-$K$4 -> 1.7251547 | D96: 188.49 | E96: 280.826 | F96: =(D96+E96)/2 -> 234.658 | G96: =F96-$K$3 -> 1.7533201 | H96: =F96-B96 -> 10.563816 | I96: =(H96-$K$2) -> 0.028165478 | J96: =G96/($K$8-$K$3) -> 0.21366787
A97: 115 | B97: 224.05675 | C97: =B97-$K$4 -> 1.6877163 | D97: 188.618 | E97: 281.752 | F97: =(D97+E97)/2 -> 235.185 | G97: =F97-$K$3 -> 2.2803201 | H97: =F97-B97 -> 11.128254 | I97: =(H97-$K$2) -> 0.59260389 | J97: =G97/($K$8-$K$3) -> 0.27789058 | K97: 10
A98: 116 | B98: 224.05115 | C98: =B98-$K$4 -> 1.6821157 | D98: 188.261 | E98: 281.146 | F98: =(D98+E98)/2 -> 234.7035 | G98: =F98-$K$3 -> 1.7988201 | H98: =F98-B98 -> 10.652355 | I98: =(H98-$K$2) -> 0.1167045 | J98: =G98/($K$8-$K$3) -> 0.21921272
A99: 117 | B99: 224.02407 | C99: =B99-$K$4 -> 1.6550374 | D99: 188.296 | E99: 280.88 | F99: =(D99+E99)/2 -> 234.588 | G99: =F99-$K$3 -> 1.6833201 | H99: =F99-B99 -> 10.563933 | I99: =(H99-$K$2) -> 0.028282721 | J99: =G99/($K$8-$K$3) -> 0.20513734
A100: 118 | B100: 224.17082 | C100: =B100-$K$4 -> 1.8017923 | D100: 188.764 | E100: 281.336 | F100: =(D100+E100)/2 -> 235.05 | G100: =F100-$K$3 -> 2.1453201 | H100: =F100-B100 -> 10.879178 | I100: =(H100-$K$2) -> 0.34352783 | J100: =G100/($K$8-$K$3) -> 0.26143885
A101: 119 | B101: 224.20222 | C101: =B101-$K$4 -> 1.833194 | D101: 188.392 | E101: 281.788 | F101: =(D101+E101)/2 -> 235.09 | G101: =F101-$K$3 -> 2.1853201 | H101: =F101-B101 -> 10.887777 | I101: =(H101-$K$2) -> 0.35212615 | J101: =G101/($K$8-$K$3) -> 0.26631343
A102: 120 | B102: 224.10934 | C102: =B102-$K$4 -> 1.7403148 | D102: 188.205 | E102: 281.051 | F102: =(D102+E102)/2 -> 234.628 | G102: =F102-$K$3 -> 1.7233201 | H102: =F102-B102 -> 10.518656 | I102: =(H102-$K$2) -> -0.016994684 | J102: =G102/($K$8-$K$3) -> 0.21001193
A103: 121 | B103: 223.98497 | C103: =B103-$K$4 -> 1.6159418 | D103: 188.238 | E103: 281.197 | F103: =(D103+E103)/2 -> 234.7175 | G103: =F103-$K$3 -> 1.8128201 | H103: =F103-B103 -> 10.732529 | I103: =(H103-$K$2) -> 0.19687838 | J103: =G103/($K$8-$K$3) -> 0.22091883
A104: 122 | B104: 224.04186 | C104: =B104-$K$4 -> 1.6728263 | D104: 188.203 | E104: 280.985 | F104: =(D104+E104)/2 -> 234.594 | G104: =F104-$K$3 -> 1.6893201 | H104: =F104-B104 -> 10.552144 | I104: =(H104-$K$2) -> 0.016493815 | J104: =G104/($K$8-$K$3) -> 0.20586853
A105: 123 | B105: 224.00636 | C105: =B105-$K$4 -> 1.6373307 | D105: 188.203 | E105: 280.772 | F105: =(D105+E105)/2 -> 234.4875 | G105: =F105-$K$3 -> 1.5828201 | H105: =F105-B105 -> 10.48114 | I105: =(H105-$K$2) -> -0.054510516 | J105: =G105/($K$8-$K$3) -> 0.19288994
A106: 124 | B106: 223.97086 | C106: =B106-$K$4 -> 1.601835 | D106: 188.321 | E106: 280.56 | F106: =(D106+E106)/2 -> 234.4405 | G106: =F106-$K$3 -> 1.5358201 | H106: =F106-B106 -> 10.469636 | I106: =(H106-$K$2) -> -0.066014847 | J106: =G106/($K$8-$K$3) -> 0.1871623
...

Sheet Annual Temp at Depth
A1: sol | B1: motor_mean_of_6h_13h | C1: motor_mean_of_24h | D1: Diff | E1: motor_mean_of_6h_13h_interpolated | G1: Temperature variation | H1: recalibration correction applied from sol 680 on
A2: 20 | E2: 226.587 | G2: =E2-$F$4 -> 6.7203809
A3: 21 | E3: 226.446 | F3: average Temperature | G3: =E3-$F$4 -> 6.5793809
A4: 22 | E4: 226.305 | F4: =AVERAGE(E2:E1227) -> 219.86662 | G4: =E4-$F$4 -> 6.4383809
A5: 23 | B5: 226.163 | C5: 220.415 | D5: =C5-B5 -> -5.748 | E5: 226.163 | G5: =E5-$F$4 -> 6.2963809
A6: 24 | C6: 219.82 | E6: 225.728 | F6: Min Max | G6: =E6-$F$4 -> 5.8613809
A7: 25 | C7: 221.565 | E7: 225.292 | F7: =MAX(G2:G1227) -> 8.5653809 | G7: =E7-$F$4 -> 5.4253809
A8: 26 | B8: 224.856 | C8: 219.63 | D8: =C8-B8 -> -5.226 | E8: 224.856 | F8: =MIN(G2:G1227) -> -7.8956191 | G8: =E8-$F$4 -> 4.9893809
A9: 27 | C9: 221.571 | E9: 225.189 | G9: =E9-$F$4 -> 5.3223809
A10: 28 | B10: 225.522 | C10: 220.199 | D10: =C10-B10 -> -5.323 | E10: 225.522 | F10: Range | G10: =E10-$F$4 -> 5.6553809
A11: 29 | B11: 225.916 | C11: 220.612 | D11: =C11-B11 -> -5.304 | E11: 225.916 | F11: =F7-F8 -> 16.461 | G11: =E11-$F$4 -> 6.0493809
A12: 30 | C12: 221.807 | E12: 226.049 | G12: =E12-$F$4 -> 6.1823809
A13: 31 | C13: 219.975 | E13: 226.181 | G13: =E13-$F$4 -> 6.3143809
A14: 32 | C14: 221.661 | E14: 226.314 | G14: =E14-$F$4 -> 6.4473809
A15: 33 | C15: 218.793 | E15: 226.447 | G15: =E15-$F$4 -> 6.5803809
A16: 34 | B16: 226.579 | C16: 220.612 | D16: =C16-B16 -> -5.967 | E16: 226.579 | G16: =E16-$F$4 -> 6.7123809
A17: 35 | B17: 227.084 | C17: 221.466 | D17: =C17-B17 -> -5.618 | E17: 227.084 | G17: =E17-$F$4 -> 7.2173809
A18: 36 | B18: 227.342 | C18: 221.524 | D18: =C18-B18 -> -5.818 | E18: 227.342 | G18: =E18-$F$4 -> 7.4753809
A19: 37 | E19: 227.232 | G19: =E19-$F$4 -> 7.3653809
A20: 38 | C20: 219.416 | E20: 227.122 | G20: =E20-$F$4 -> 7.2553809
A21: 39 | B21: 227.012 | C21: 220.965 | D21: =C21-B21 -> -6.047 | E21: 227.012 | G21: =E21-$F$4 -> 7.1453809
A22: 40 | B22: 227.236 | C22: 221.031 | D22: =C22-B22 -> -6.205 | E22: 227.236 | G22: =E22-$F$4 -> 7.3693809
A23: 41 | B23: 227.718 | C23: 222.132 | D23: =C23-B23 -> -5.586 | E23: 227.718 | G23: =E23-$F$4 -> 7.8513809
A24: 42 | B24: 227.262 | C24: 222.128 | D24: =C24-B24 -> -5.134 | E24: 227.262 | G24: =E24-$F$4 -> 7.3953809
A25: 43 | B25: 228.004 | C25: 222.272 | D25: =C25-B25 -> -5.732 | E25: 228.004 | G25: =E25-$F$4 -> 8.1373809
A26: 44 | B26: 226.576 | C26: 221.212 | D26: =C26-B26 -> -5.364 | E26: 226.576 | G26: =E26-$F$4 -> 6.7093809
A27: 45 | B27: 226.659 | C27: 221.393 | D27: =C27-B27 -> -5.266 | E27: 226.659 | G27: =E27-$F$4 -> 6.7923809
A28: 46 | C28: 220.945 | E28: 226.48 | G28: =E28-$F$4 -> 6.6133809
A29: 47 | B29: 226.301 | C29: 221.685 | D29: =C29-B29 -> -4.616 | E29: 226.301 | G29: =E29-$F$4 -> 6.4343809
A30: 48 | B30: 226.495 | C30: 221.685 | D30: =C30-B30 -> -4.81 | E30: 226.495 | G30: =E30-$F$4 -> 6.6283809
A31: 49 | B31: 227.179 | C31: 221.195 | D31: =C31-B31 -> -5.984 | E31: 227.179 | G31: =E31-$F$4 -> 7.3123809
A32: 50 | B32: 228.095 | C32: 221.074 | D32: =C32-B32 -> -7.021 | E32: 228.095 | G32: =E32-$F$4 -> 8.2283809
A33: 51 | B33: 226.661 | C33: 220.978 | D33: =C33-B33 -> -5.683 | E33: 226.661 | G33: =E33-$F$4 -> 6.7943809
A34: 52 | B34: 227.235 | C34: 221.213 | D34: =C34-B34 -> -6.022 | E34: 227.235 | G34: =E34-$F$4 -> 7.3683809
A35: 53 | B35: 227.568 | C35: 221.236 | D35: =C35-B35 -> -6.332 | E35: 227.568 | G35: =E35-$F$4 -> 7.7013809
A36: 54 | B36: 227.734 | C36: 221.404 | D36: =C36-B36 -> -6.33 | E36: 227.734 | G36: =E36-$F$4 -> 7.8673809
A37: 55 | B37: 227.81 | C37: 221.207 | D37: =C37-B37 -> -6.603 | E37: 227.81 | G37: =E37-$F$4 -> 7.9433809
A38: 56 | B38: 228.006 | C38: 221.17 | D38: =C38-B38 -> -6.836 | E38: 228.006 | G38: =E38-$F$4 -> 8.1393809
A39: 57 | E39: 227.839 | G39: =E39-$F$4 -> 7.9723809
A40: 58 | E40: 227.672 | G40: =E40-$F$4 -> 7.8053809
...

Sheet 2nd year Temp (Fig. 2)
A1: sol | B1: Sol since sol 680 | C1: Mole Temp | D1: Mole Temp recalibrated | E1: Delta | F1: Mole Temp Variation before recalibration | G1: Temp Var recalibrated | H1: Temp Var scaled recalibrated | I1: TEM-A | J1: RAD 24h Data | K1: Rad Daten (24h av, modelled after yr 1) | L1: RAD Temp Var 24h average | M1: RAD scaled Temp Var
A2: 681 | B2: 1 | C2: ='Annual Temp at Depth'!E663 -> 221.682 | D2: ='Annual Temp at Depth'!H663 -> 222.31078 | E2: =D2-C2 -> 0.62877878 | F2: =C2-$C$568 -> 3.7193504 | G2: =D2-$D$568 -> 3.7280008 | H2: =(D2-$D$568)/($D$569-$D$568) -> 0.53742939 | I2: 222.34869 | K2: ='RAD Data'!B663 -> 223.88628 | L2: =K2-$K$568 -> 2.2158307 | M2: =(K2-$K$568)/($K$569-$K$568) -> 0.31083135
A3: 682 | B3: 2 | C3: ='Annual Temp at Depth'!E664 -> 221.723 | D3: ='Annual Temp at Depth'!H664 -> 222.35061 | E3: =D3-C3 -> 0.62761468 | F3: =C3-$C$568 -> 3.7603504 | G3: =D3-$D$568 -> 3.7678367 | H3: =(D3-$D$568)/($D$569-$D$568) -> 0.54317215 | K3: ='RAD Data'!B664 -> 223.85115 | L3: =K3-$K$568 -> 2.1806945 | M3: =(K3-$K$568)/($K$569-$K$568) -> 0.30590254
A4: 683 | B4: 3 | C4: ='Annual Temp at Depth'!E665 -> 221.763 | D4: ='Annual Temp at Depth'!H665 -> 222.38947 | E4: =D4-C4 -> 0.62647302 | F4: =C4-$C$568 -> 3.8003504 | G4: =D4-$D$568 -> 3.806695 | H4: =(D4-$D$568)/($D$569-$D$568) -> 0.54877397 | K4: ='RAD Data'!B665 -> 223.81601 | L4: =K4-$K$568 -> 2.1455584 | M4: =(K4-$K$568)/($K$569-$K$568) -> 0.30097373
A5: 684 | B5: 4 | C5: ='Annual Temp at Depth'!E666 -> 221.804 | D5: ='Annual Temp at Depth'!H666 -> 222.42935 | E5: =D5-C5 -> 0.62535368 | F5: =C5-$C$568 -> 3.8413504 | G5: =D5-$D$568 -> 3.8465757 | H5: =(D5-$D$568)/($D$569-$D$568) -> 0.55452318 | K5: ='RAD Data'!B666 -> 223.70671 | L5: =K5-$K$568 -> 2.0362523 | M5: =(K5-$K$568)/($K$569-$K$568) -> 0.28564053
A6: 685 | B6: 5 | C6: ='Annual Temp at Depth'!E667 -> 221.844 | D6: ='Annual Temp at Depth'!H667 -> 222.46826 | E6: =D6-C6 -> 0.62425655 | F6: =C6-$C$568 -> 3.8813504 | G6: =D6-$D$568 -> 3.8854785 | H6: =(D6-$D$568)/($D$569-$D$568) -> 0.56013142 | K6: ='RAD Data'!B667 -> 223.7168 | L6: =K6-$K$568 -> 2.0463483 | M6: =(K6-$K$568)/($K$569-$K$568) -> 0.28705677
A7: 686 | B7: 6 | C7: ='Annual Temp at Depth'!E668 -> 221.885 | D7: ='Annual Temp at Depth'!H668 -> 222.50818 | E7: =D7-C7 -> 0.62318151 | F7: =C7-$C$568 -> 3.9223504 | G7: =D7-$D$568 -> 3.9254035 | H7: =(D7-$D$568)/($D$569-$D$568) -> 0.56588701 | K7: ='RAD Data'!B668 -> 223.7934 | L7: =K7-$K$568 -> 2.1229432 | M7: =(K7-$K$568)/($K$569-$K$568) -> 0.29780132
A8: 687 | B8: 7 | C8: ='Annual Temp at Depth'!E669 -> 221.925 | D8: ='Annual Temp at Depth'!H669 -> 222.54713 | E8: =D8-C8 -> 0.62212844 | F8: =C8-$C$568 -> 3.9623504 | G8: =D8-$D$568 -> 3.9643504 | H8: =(D8-$D$568)/($D$569-$D$568) -> 0.57150161 | K8: ='RAD Data'!B669 -> 223.98939 | L8: =K8-$K$568 -> 2.3189385 | M8: =(K8-$K$568)/($K$569-$K$568) -> 0.32529506
A9: 688 | B9: 8 | C9: ='Annual Temp at Depth'!E670 -> 221.799 | D9: ='Annual Temp at Depth'!H670 -> 222.4201 | E9: =D9-C9 -> 0.62109723 | F9: =C9-$C$568 -> 3.8363504 | G9: =D9-$D$568 -> 3.8373192 | H9: =(D9-$D$568)/($D$569-$D$568) -> 0.55318876 | K9: ='RAD Data'!B670 -> 223.9999 | L9: =K9-$K$568 -> 2.3294481 | M9: =(K9-$K$568)/($K$569-$K$568) -> 0.32676932
A10: 689 | B10: 9 | C10: ='Annual Temp at Depth'!E671 -> 221.674 | D10: ='Annual Temp at Depth'!H671 -> 222.29409 | E10: =D10-C10 -> 0.62008775 | F10: =C10-$C$568 -> 3.7113504 | G10: =D10-$D$568 -> 3.7113097 | H10: =(D10-$D$568)/($D$569-$D$568) -> 0.53502321 | K10: ='RAD Data'!B671 -> 223.98256 | L10: =K10-$K$568 -> 2.312108 | M10: =(K10-$K$568)/($K$569-$K$568) -> 0.32433689
A11: 690 | B11: 10 | C11: ='Annual Temp at Depth'!E672 -> 221.548 | D11: ='Annual Temp at Depth'!H672 -> 222.1671 | E11: =D11-C11 -> 0.61909991 | F11: =C11-$C$568 -> 3.5853504 | G11: =D11-$D$568 -> 3.5843219 | H11: =(D11-$D$568)/($D$569-$D$568) -> 0.51671662 | K11: ='RAD Data'!B672 -> 223.99334 | L11: =K11-$K$568 -> 2.3228873 | M11: =(K11-$K$568)/($K$569-$K$568) -> 0.32584899
A12: 691 | B12: 11 | C12: ='Annual Temp at Depth'!E673 -> 221.506 | D12: ='Annual Temp at Depth'!H673 -> 222.12413 | E12: =D12-C12 -> 0.61813356 | F12: =C12-$C$568 -> 3.5433504 | G12: =D12-$D$568 -> 3.5413555 | H12: =(D12-$D$568)/($D$569-$D$568) -> 0.51052258 | K12: ='RAD Data'!B673 -> 224.00425 | L12: =K12-$K$568 -> 2.3338004 | M12: =(K12-$K$568)/($K$569-$K$568) -> 0.32737986
A13: 692 | B13: 12 | C13: ='Annual Temp at Depth'!E674 -> 221.464 | D13: ='Annual Temp at Depth'!H674 -> 222.08119 | E13: =D13-C13 -> 0.61718861 | F13: =C13-$C$568 -> 3.5013504 | G13: =D13-$D$568 -> 3.4984106 | H13: =(D13-$D$568)/($D$569-$D$568) -> 0.50433163 | K13: ='RAD Data'!B674 -> 223.87325 | L13: =K13-$K$568 -> 2.2027959 | M13: =(K13-$K$568)/($K$569-$K$568) -> 0.30900286
A14: 693 | B14: 13 | C14: ='Annual Temp at Depth'!E675 -> 221.422 | D14: ='Annual Temp at Depth'!H675 -> 222.03826 | E14: =D14-C14 -> 0.61626493 | F14: =C14-$C$568 -> 3.4593504 | G14: =D14-$D$568 -> 3.4554869 | H14: =(D14-$D$568)/($D$569-$D$568) -> 0.49814374 | K14: ='RAD Data'!B675 -> 223.74225 | L14: =K14-$K$568 -> 2.0717913 | M14: =(K14-$K$568)/($K$569-$K$568) -> 0.29062586
... A16: 695 | B16: 15 | C16: ='Annual Temp at Depth'!E677 -> 221.337 | D16: ='Annual Temp at Depth'!H677 -> 221.95148 | E16: =D16-C16 -> 0.61448092 | F16: =C16-$C$568 -> 3.3743504 | G16: =D16-$D$568 -> 3.3687029 | H16: =(D16-$D$568)/($D$569-$D$568) -> 0.48563294 | K16: ='RAD Data'!B677 -> 223.48024 | L16: =K16-$K$568 -> 1.8097822 | M16: =(K16-$K$568)/($K$569-$K$568) -> 0.25387185
A17: 696 | B17: 16 | C17: ='Annual Temp at Depth'!E678 -> 221.295 | D17: ='Annual Temp at Depth'!H678 -> 221.90862 | E17: =D17-C17 -> 0.61362036 | F17: =C17-$C$568 -> 3.3323504 | G17: =D17-$D$568 -> 3.3258423 | H17: =(D17-$D$568)/($D$569-$D$568) -> 0.47945415 | J17: 223.535 | K17: ='RAD Data'!B678 -> 223.34923 | L17: =K17-$K$568 -> 1.6787776 | M17: =(K17-$K$568)/($K$569-$K$568) -> 0.23549485
A18: 697 | B18: 17 | C18: ='Annual Temp at Depth'!E679 -> 221.253 | D18: ='Annual Temp at Depth'!H679 -> 221.86578 | E18: =D18-C18 -> 0.6127806 | F18: =C18-$C$568 -> 3.2903504 | G18: =D18-$D$568 -> 3.2830026 | H18: =(D18-$D$568)/($D$569-$D$568) -> 0.47327836 | K18: ='RAD Data'!B679 -> 223.36093 | L18: =K18-$K$568 -> 1.6904732 | M18: =(K18-$K$568)/($K$569-$K$568) -> 0.23713547
A19: 698 | B19: 18 | C19: ='Annual Temp at Depth'!E680 -> 221.211 | D19: ='Annual Temp at Depth'!H680 -> 221.82296 | E19: =D19-C19 -> 0.61196153 | F19: =C19-$C$568 -> 3.2483504 | G19: =D19-$D$568 -> 3.2401835 | H19: =(D19-$D$568)/($D$569-$D$568) -> 0.46710555 | K19: ='RAD Data'!B680 -> 223.55588 | L19: =K19-$K$568 -> 1.8854249 | M19: =(K19-$K$568)/($K$569-$K$568) -> 0.26448283
A20: 699 | B20: 19 | C20: ='Annual Temp at Depth'!E681 -> 221.169 | D20: ='Annual Temp at Depth'!H681 -> 221.78016 | E20: =D20-C20 -> 0.61116304 | F20: =C20-$C$568 -> 3.2063504 | G20: =D20-$D$568 -> 3.197385 | H20: =(D20-$D$568)/($D$569-$D$568) -> 0.46093571 | K20: ='RAD Data'!B681 -> 223.75083 | L20: =K20-$K$568 -> 2.0803766 | M20: =(K20-$K$568)/($K$569-$K$568) -> 0.29183018
A21: 700 | B21: 20 | C21: ='Annual Temp at Depth'!E682 -> 221.126 | D21: ='Annual Temp at Depth'!H682 -> 221.73639 | E21: =D21-C21 -> 0.610385 | F21: =C21-$C$568 -> 3.1633504 | G21: =D21-$D$568 -> 3.153607 | H21: =(D21-$D$568)/($D$569-$D$568) -> 0.45462466 | K21: ='RAD Data'!B682 -> 223.94578 | L21: =K21-$K$568 -> 2.2753283 | M21: =(K21-$K$568)/($K$569-$K$568) -> 0.31917753
A22: 701 | B22: 21 | C22: ='Annual Temp at Depth'!E683 -> 221.084 | D22: ='Annual Temp at Depth'!H683 -> 221.69363 | E22: =D22-C22 -> 0.6096273 | F22: =C22-$C$568 -> 3.1213504 | G22: =D22-$D$568 -> 3.1108493 | H22: =(D22-$D$568)/($D$569-$D$568) -> 0.4484607 | K22: ='RAD Data'!B683 -> 224.14073 | L22: =K22-$K$568 -> 2.47028 | M22: =(K22-$K$568)/($K$569-$K$568) -> 0.34652488
A23: 702 | B23: 22 | C23: ='Annual Temp at Depth'!E684 -> 221.042 | D23: ='Annual Temp at Depth'!H684 -> 221.65089 | E23: =D23-C23 -> 0.60888982 | F23: =C23-$C$568 -> 3.0793504 | G23: =D23-$D$568 -> 3.0681118 | H23: =(D23-$D$568)/($D$569-$D$568) -> 0.44229966 | K23: ='RAD Data'!B684 -> 224.15305 | L23: =K23-$K$568 -> 2.4826002 | M23: =(K23-$K$568)/($K$569-$K$568) -> 0.34825312
A24: 703 | B24: 23 | C24: ='Annual Temp at Depth'!E685 -> 220.991 | D24: ='Annual Temp at Depth'!H685 -> 221.59917 | E24: =D24-C24 -> 0.60817245 | F24: =C24-$C$568 -> 3.0283504 | G24: =D24-$D$568 -> 3.0163944 | H24: =(D24-$D$568)/($D$569-$D$568) -> 0.43484407 | K24: ='RAD Data'!B685 -> 223.73832 | L24: =K24-$K$568 -> 2.067871 | M24: =(K24-$K$568)/($K$569-$K$568) -> 0.29007593
A25: 704 | B25: 24 | C25: ='Annual Temp at Depth'!E686 -> 220.939 | D25: ='Annual Temp at Depth'!H686 -> 221.54648 | E25: =D25-C25 -> 0.60747507 | F25: =C25-$C$568 -> 2.9763504 | G25: =D25-$D$568 -> 2.963697 | H25: =(D25-$D$568)/($D$569-$D$568) -> 0.42724721 | K25: ='RAD Data'!B686 -> 223.73949 | L25: =K25-$K$568 -> 2.069033 | M25: =(K25-$K$568)/($K$569-$K$568) -> 0.29023892
A26: 705 | B26: 25 | C26: ='Annual Temp at Depth'!E687 -> 220.913 | D26: ='Annual Temp at Depth'!H687 -> 221.5198 | E26: =D26-C26 -> 0.60679756 | F26: =C26-$C$568 -> 2.9503504 | G26: =D26-$D$568 -> 2.9370195 | H26: =(D26-$D$568)/($D$569-$D$568) -> 0.42340137 | K26: ='RAD Data'!B687 -> 223.74065 | L26: =K26-$K$568 -> 2.0701949 | M26: =(K26-$K$568)/($K$569-$K$568) -> 0.29040192
A27: 706 | B27: 26 | C27: ='Annual Temp at Depth'!E688 -> 220.886 | D27: ='Annual Temp at Depth'!H688 -> 221.49214 | E27: =D27-C27 -> 0.6061398 | F27: =C27-$C$568 -> 2.9233504 | G27: =D27-$D$568 -> 2.9093618 | H27: =(D27-$D$568)/($D$569-$D$568) -> 0.41941422 | K27: ='RAD Data'!B688 -> 223.74181 | L27: =K27-$K$568 -> 2.0713569 | M27: =(K27-$K$568)/($K$569-$K$568) -> 0.29056492
A28: 707 | B28: 27 | C28: ='Annual Temp at Depth'!E689 -> 220.86 | D28: ='Annual Temp at Depth'!H689 -> 221.4655 | E28: =D28-C28 -> 0.60550168 | F28: =C28-$C$568 -> 2.8973504 | G28: =D28-$D$568 -> 2.8827237 | H28: =(D28-$D$568)/($D$569-$D$568) -> 0.41557407 | K28: ='RAD Data'!B689 -> 223.74297 | L28: =K28-$K$568 -> 2.0725188 | M28: =(K28-$K$568)/($K$569-$K$568) -> 0.29072791
A29: 708 | B29: 28 | C29: ='Annual Temp at Depth'!E690 -> 220.833 | D29: ='Annual Temp at Depth'!H690 -> 221.43788 | E29: =D29-C29 -> 0.60488309 | F29: =C29-$C$568 -> 2.8703504 | G29: =D29-$D$568 -> 2.8551051 | H29: =(D29-$D$568)/($D$569-$D$568) -> 0.41159256 | K29: ='RAD Data'!B690 -> 223.74413 | L29: =K29-$K$568 -> 2.0736808 | M29: =(K29-$K$568)/($K$569-$K$568) -> 0.29089091
... A116: 795 | B116: 115 | C116: ='Annual Temp at Depth'!E777 -> 219.964 | D116: ='Annual Temp at Depth'!H777 -> 220.57654 | E116: =D116-C116 -> 0.61253876 | F116: =C116-$C$568 -> 2.0013504 | G116: =D116-$D$568 -> 1.9937607 | H116: =(D116-$D$568)/($D$569-$D$568) -> 0.28742098 | K116: ='RAD Data'!B777 -> 222.95351 | L116: =K116-$K$568 -> 1.283058 | M116: =(K116-$K$568)/($K$569-$K$568) -> 0.17998426
A117: 796 | B117: 116 | C117: ='Annual Temp at Depth'!E778 -> 220.23 | D117: ='Annual Temp at Depth'!H778 -> 220.84318 | E117: =D117-C117 -> 0.61318097 | F117: =C117-$C$568 -> 2.2673504 | G117: =D117-$D$568 -> 2.2604029 | H117: =(D117-$D$568)/($D$569-$D$568) -> 0.32586018 | I117: 220.79462 | K117: ='RAD Data'!B778 -> 222.87124 | L117: =K117-$K$568 -> 1.2007858 | M117: =(K117-$K$568)/($K$569-$K$568) -> 0.16844331
A118: 797 | B118: 117 | C118: ='Annual Temp at Depth'!E779 -> 220.172 | D118: ='Annual Temp at Depth'!H779 -> 220.78583 | E118: =D118-C118 -> 0.61383232 | F118: =C118-$C$568 -> 2.2093504 | G118: =D118-$D$568 -> 2.2030543 | H118: =(D118-$D$568)/($D$569-$D$568) -> 0.31759278 | K118: ='RAD Data'!B779 -> 222.78897 | L118: =K118-$K$568 -> 1.1185135 | M118: =(K118-$K$568)/($K$569-$K$568) -> 0.15690236
A119: 798 | B119: 118 | C119: ='Annual Temp at Depth'!E780 -> 220.114 | D119: ='Annual Temp at Depth'!H780 -> 220.72849 | E119: =D119-C119 -> 0.61449269 | F119: =C119-$C$568 -> 2.1513504 | G119: =D119-$D$568 -> 2.1457147 | H119: =(D119-$D$568)/($D$569-$D$568) -> 0.30932669 | K119: ='RAD Data'!B780 -> 222.7067 | L119: =K119-$K$568 -> 1.0362413 | M119: =(K119-$K$568)/($K$569-$K$568) -> 0.14536141
A120: 799 | B120: 119 | C120: ='Annual Temp at Depth'!E781 -> 220.056 | D120: ='Annual Temp at Depth'!H781 -> 220.67116 | E120: =D120-C120 -> 0.61516195 | F120: =C120-$C$568 -> 2.0933504 | G120: =D120-$D$568 -> 2.0883839 | H120: =(D120-$D$568)/($D$569-$D$568) -> 0.30106188 | K120: ='RAD Data'!B781 -> 222.62442 | L120: =K120-$K$568 -> 0.95396905 | M120: =(K120-$K$568)/($K$569-$K$568) -> 0.13382046
A121: 800 | B121: 120 | C121: ='Annual Temp at Depth'!E782 -> 219.998 | D121: ='Annual Temp at Depth'!H782 -> 220.61384 | E121: =D121-C121 -> 0.61584 | F121: =C121-$C$568 -> 2.0353504 | G121: =D121-$D$568 -> 2.031062 | H121: =(D121-$D$568)/($D$569-$D$568) -> 0.29279833 | K121: ='RAD Data'!B782 -> 222.54215 | L121: =K121-$K$568 -> 0.87169681 | M121: =(K121-$K$568)/($K$569-$K$568) -> 0.12227951
A122: 801 | B122: 121 | C122: ='Annual Temp at Depth'!E783 -> 219.94 | D122: ='Annual Temp at Depth'!H783 -> 220.55653 | E122: =D122-C122 -> 0.61652671 | F122: =C122-$C$568 -> 1.9773504 | G122: =D122-$D$568 -> 1.9737487 | H122: =(D122-$D$568)/($D$569-$D$568) -> 0.28453604 | K122: ='RAD Data'!B783 -> 222.45988 | L122: =K122-$K$568 -> 0.78942457 | M122: =(K122-$K$568)/($K$569-$K$568) -> 0.11073856
A123: 802 | B123: 122 | C123: ='Annual Temp at Depth'!E784 -> 219.882 | D123: ='Annual Temp at Depth'!H784 -> 220.49922 | E123: =D123-C123 -> 0.61722198 | F123: =C123-$C$568 -> 1.9193504 | G123: =D123-$D$568 -> 1.916444 | H123: =(D123-$D$568)/($D$569-$D$568) -> 0.27627497 | K123: ='RAD Data'!B784 -> 222.37761 | L123: =K123-$K$568 -> 0.70715234 | M123: =(K123-$K$568)/($K$569-$K$568) -> 0.099197614
A124: 803 | B124: 123 | C124: ='Annual Temp at Depth'!E785 -> 219.824 | D124: ='Annual Temp at Depth'!H785 -> 220.44193 | E124: =D124-C124 -> 0.61792567 | F124: =C124-$C$568 -> 1.8613504 | G124: =D124-$D$568 -> 1.8591476 | H124: =(D124-$D$568)/($D$569-$D$568) -> 0.26801513 | K124: ='RAD Data'!B785 -> 222.29533 | L124: =K124-$K$568 -> 0.6248801 | M124: =(K124-$K$568)/($K$569-$K$568) -> 0.087656664
A125: 804 | B125: 124 | C125: ='Annual Temp at Depth'!E786 -> 219.766 | D125: ='Annual Temp at Depth'!H786 -> 220.38464 | E125: =D125-C125 -> 0.61863768 | F125: =C125-$C$568 -> 1.8033504 | G125: =D125-$D$568 -> 1.8018597 | H125: =(D125-$D$568)/($D$569-$D$568) -> 0.25975648 | K125: ='RAD Data'!B786 -> 222.21306 | L125: =K125-$K$568 -> 0.54260787 | M125: =(K125-$K$568)/($K$569-$K$568) -> 0.076115715
A126: 805 | B126: 125 | C126: ='Annual Temp at Depth'!E787 -> 219.708 | D126: ='Annual Temp at Depth'!H787 -> 220.32736 | E126: =D126-C126 -> 0.61935789 | F126: =C126-$C$568 -> 1.7453504 | G126: =D126-$D$568 -> 1.7445799 | H126: =(D126-$D$568)/($D$569-$D$568) -> 0.25149901 | K126: ='RAD Data'!B787 -> 222.13079 | L126: =K126-$K$568 -> 0.46033563 | M126: =(K126-$K$568)/($K$569-$K$568) -> 0.064574765
A127: 806 | B127: 126 | C127: ='Annual Temp at Depth'!E788 -> 219.649 | D127: ='Annual Temp at Depth'!H788 -> 220.26909 | E127: =D127-C127 -> 0.62008619 | F127: =C127-$C$568 -> 1.6863504 | G127: =D127-$D$568 -> 1.6863082 | H127: =(D127-$D$568)/($D$569-$D$568) -> 0.24309855 | K127: ='RAD Data'!B788 -> 222.04852 | L127: =K127-$K$568 -> 0.3780634 | M127: =(K127-$K$568)/($K$569-$K$568) -> 0.053033816
...

Sheet 2nd year FFT
A1: Sol since sol 600 | B1: Mole Temp re-calibrated | C1: RAD Surface Temperature | D1: 512 data points time | E1: 512 data points Mole T | F1: 512 data points RAD | G1: Scaled Mole T | H1: Scaled RAD T | I1: Period | J1: Frequency [1/sol] | K1: FFT Mole | L1: Amplitude | M1: Phase | N1: 2 log Amp | O1: FFT RAD | P1: Amplitude | Q1: Phase | R1: 2 log Amp | S1: Amplitude ratio | T1: Phasediff [sol] rad
A2: 1 | B2: 0 | C2: 0 | D2: =AVERAGE(OFFSET(A$2,(ROW(A2)-1)*1.34,,1.34)) -> 2 | E2: =AVERAGE(OFFSET(B$2,(ROW(B2)-1)*1.34,,1.34)) -> 0 | F2: =AVERAGE(OFFSET(C$2,(ROW(C2)-1)*1.34,,1.34)) -> 0 | G2: 0 | H2: 0 | I2: DC | J2: 0 | K2: 0 | L2: =2*IMABS(K2)/512 -> 0 | M2: =ATAN2(IMREAL(K2),IMAGINARY(K2)) -> #DIV/0! | N2: =2*LOG10(L2) -> #NUM! | O2: 0 | P2: =IMABS(O2)/512 -> 0
A3: 2 | B3: 0 | C3: 0 | D3: =AVERAGE(OFFSET(A$2,(ROW(A3)-1)*1.34,,1.34)) -> 3 | E3: =AVERAGE(OFFSET(B$2,(ROW(B3)-1)*1.34,,1.34)) -> 0 | F3: =AVERAGE(OFFSET(C$2,(ROW(C3)-1)*1.34,,1.34)) -> 0 | G3: 0 | H3: 0 | I3: =668.59/A2 -> 668.59 | J3: =1/I3 -> 0.0014956849 | K3: 83,167344+79,548673i | L3: =2*IMABS(K3)/512 -> 0.44955488 | M3: =ATAN2(IMREAL(K3),IMAGINARY(K3)) -> 0.76316265 | N3: =2*LOG10(L3) -> -0.69443458 | O3: 76,427160+109,060118i | P3: =2*IMABS(O3)/512 -> 0.52020956 | Q3: =ATAN2(IMREAL(O3),IMAGINARY(O3)) -> 0.959547 | R3: =2*LOG10(P3) -> -0.56764335 | S3: =L3*$E$519/P3/$F$519 -> 0.72406983 | T3: =(Q3-M3)/2/PI()*668.59 -> 20.897142
A4: 3 | B4: 0 | C4: 0 | D4: =AVERAGE(OFFSET(A$2,(ROW(A4)-1)*1.34,,1.34)) -> 5 | E4: =AVERAGE(OFFSET(B$2,(ROW(B4)-1)*1.34,,1.34)) -> 0 | F4: =AVERAGE(OFFSET(C$2,(ROW(C4)-1)*1.34,,1.34)) -> 0 | G4: 0 | H4: 0 | I4: =668.59/A3 -> 334.295 | J4: =1/I4 -> 0.0029913699 | K4: -100,794284-28,790579i | L4: =2*IMABS(K4)/512 -> 0.4094746 | M4: =ATAN2(IMREAL(K4),IMAGINARY(K4)) -> -2.8633644 | N4: =2*LOG10(L4) -> -0.77554606 | O4: -92,571968-46,849968i | P4: =2*IMABS(O4)/512 -> 0.40528146 | Q4: =ATAN2(IMREAL(O4),IMAGINARY(O4)) -> -2.673083 | R4: =2*LOG10(P4) -> -0.78448652 | S4: =L4*$E$519/P4/$F$519 -> 0.84653768 | T4: =Q3-M3 -> 0.19638435
A5: 4 | B5: 0 | C5: 0 | D5: =AVERAGE(OFFSET(A$2,(ROW(A5)-1)*1.34,,1.34)) -> 6 | E5: =AVERAGE(OFFSET(B$2,(ROW(B5)-1)*1.34,,1.34)) -> 0 | F5: =AVERAGE(OFFSET(C$2,(ROW(C5)-1)*1.34,,1.34)) -> 0 | G5: 0 | H5: 0 | I5: =668.59/A4 -> 222.86333 | J5: =1/I5 -> 0.0044870548 | K5: -18,382752-16,030077i | L5: =2*IMABS(K5)/512 -> 0.095274786 | M5: =ATAN2(IMREAL(K5),IMAGINARY(K5)) -> -2.4244545 | N5: =2*LOG10(L5) -> -2.042044 | O5: -16,052580-20,957309i | P5: =2*IMABS(O5)/512 -> 0.10312013 | Q5: =ATAN2(IMREAL(O5),IMAGINARY(O5)) -> -2.2244374 | R5: =2*LOG10(P5) -> -1.9733131 | S5: =L5*$E$519/P5/$F$519 -> 0.77412414 | T5: =20/668.59*2*PI() -> 0.18795331
A6: 5 | B6: 0 | C6: 0 | D6: =AVERAGE(OFFSET(A$2,(ROW(A6)-1)*1.34,,1.34)) -> 7 | E6: =AVERAGE(OFFSET(B$2,(ROW(B6)-1)*1.34,,1.34)) -> 0 | F6: =AVERAGE(OFFSET(C$2,(ROW(C6)-1)*1.34,,1.34)) -> 0 | G6: 0 | H6: 0 | I6: =668.59/A5 -> 167.1475 | J6: =1/I6 -> 0.0059827398 | K6: 19,172270-5,495489i | L6: =2*IMABS(K6)/512 -> 0.077907543 | M6: =ATAN2(IMREAL(K6),IMAGINARY(K6)) -> -0.27915287 | N6: =2*LOG10(L6) -> -2.216841 | O6: 17,273707-3,283189i | P6: =2*IMABS(O6)/512 -> 0.068683415 | Q6: =ATAN2(IMREAL(O6),IMAGINARY(O6)) -> -0.18782814 | R6: =2*LOG10(P6) -> -2.3262962 | S6: =L6*$E$519/P6/$F$519 -> 0.950394
A7: 6 | B7: 0 | C7: 0 | D7: =AVERAGE(OFFSET(A$2,(ROW(A7)-1)*1.34,,1.34)) -> 9 | E7: =AVERAGE(OFFSET(B$2,(ROW(B7)-1)*1.34,,1.34)) -> 0 | F7: =AVERAGE(OFFSET(C$2,(ROW(C7)-1)*1.34,,1.34)) -> 0 | G7: 0 | H7: 0 | I7: =668.59/A6 -> 133.718 | J7: =1/I7 -> 0.0074784247 | K7: 23,472041+4,012436i | L7: =2*IMABS(K7)/512 -> 0.093017676 | M7: =ATAN2(IMREAL(K7),IMAGINARY(K7)) -> 0.1693088 | N7: =2*LOG10(L7) -> -2.062869 | O7: 17,773934+10,519575i | P7: =2*IMABS(O7)/512 -> 0.080678408 | Q7: =ATAN2(IMREAL(O7),IMAGINARY(O7)) -> 0.53440831 | R7: =2*LOG10(P7) -> -2.1864854 | S7: =L7*$E$519/P7/$F$519 -> 0.9660158
A8: 7 | B8: 0 | C8: 0 | D8: =AVERAGE(OFFSET(A$2,(ROW(A8)-1)*1.34,,1.34)) -> 10 | E8: =AVERAGE(OFFSET(B$2,(ROW(B8)-1)*1.34,,1.34)) -> 0 | F8: =AVERAGE(OFFSET(C$2,(ROW(C8)-1)*1.34,,1.34)) -> 0 | G8: 0 | H8: 0 | I8: =668.59/A7 -> 111.43167 | J8: =1/I8 -> 0.0089741097 | K8: 7,465729+5,559640i | L8: =2*IMABS(K8)/512 -> 0.036361021 | M8: =ATAN2(IMREAL(K8),IMAGINARY(K8)) -> 0.64009286 | N8: =2*LOG10(L8) -> -2.8787279 | O8: 10,988790+3,930002i | P8: =2*IMABS(O8)/512 -> 0.045587531 | Q8: =ATAN2(IMREAL(O8),IMAGINARY(O8)) -> 0.34346245 | R8: =2*LOG10(P8) -> -2.6823079 | S8: =L8*$E$519/P8/$F$519 -> 0.66829168
A9: 8 | B9: 0 | C9: 0 | D9: =AVERAGE(OFFSET(A$2,(ROW(A9)-1)*1.34,,1.34)) -> 11 | E9: =AVERAGE(OFFSET(B$2,(ROW(B9)-1)*1.34,,1.34)) -> 0 | F9: =AVERAGE(OFFSET(C$2,(ROW(C9)-1)*1.34,,1.34)) -> 0 | G9: 0 | H9: 0 | I9: =668.59/A8 -> 95.512857 | J9: =1/I9 -> 0.010469795 | K9: -3,636172+4,432437i | L9: =2*IMABS(K9)/512 -> 0.022394857 | M9: =ATAN2(IMREAL(K9),IMAGINARY(K9)) -> 2.2578262 | N9: =2*LOG10(L9) -> -3.2997034 | O9: -2,042921+5,739391i | P9: =2*IMABS(O9)/512 -> 0.023797411 | Q9: =ATAN2(IMREAL(O9),IMAGINARY(O9)) -> 1.9127596 | R9: =2*LOG10(P9) -> -3.2469406 | S9: =L9*$E$519/P9/$F$519 -> 0.7884872
A10: 9 | B10: 0 | C10: 0 | D10: =AVERAGE(OFFSET(A$2,(ROW(A10)-1)*1.34,,1.34)) -> 13 | E10: =AVERAGE(OFFSET(B$2,(ROW(B10)-1)*1.34,,1.34)) -> 0 | F10: =AVERAGE(OFFSET(C$2,(ROW(C10)-1)*1.34,,1.34)) -> 0 | G10: 0 | H10: 0 | I10: =668.59/A9 -> 83.57375 | J10: =1/I10 -> 0.01196548 | K10: -9,698204+0,163904i | L10: =2*IMABS(K10)/512 -> 0.037889019 | M10: =ATAN2(IMREAL(K10),IMAGINARY(K10)) -> 3.1246938 | N10: =2*LOG10(L10) -> -2.8429733 | O10: -11,713322-6,256084i | P10: =2*IMABS(O10)/512 -> 0.051872367 | Q10: =ATAN2(IMREAL(O10),IMAGINARY(O10)) -> -2.6510387 | R10: =2*LOG10(P10) -> -2.5701279 | S10: =L10*$E$519/P10/$F$519 -> 0.61200273
A11: 10 | B11: 0 | C11: 0 | D11: =AVERAGE(OFFSET(A$2,(ROW(A11)-1)*1.34,,1.34)) -> 14 | E11: =AVERAGE(OFFSET(B$2,(ROW(B11)-1)*1.34,,1.34)) -> 0 | F11: =AVERAGE(OFFSET(C$2,(ROW(C11)-1)*1.34,,1.34)) -> 0 | G11: 0 | H11: 0 | I11: =668.59/A10 -> 74.287778 | J11: =1/I11 -> 0.013461165 | K11: -6,007461-0,441813i | L11: =2*IMABS(K11)/512 -> 0.023530021 | M11: =ATAN2(IMREAL(K11),IMAGINARY(K11)) -> -3.0681808 | N11: =2*LOG10(L11) -> -3.2567554 | O11: -5,803652-0,105562i | P11: =2*IMABS(O11)/512 -> 0.022674265 | Q11: =ATAN2(IMREAL(O11),IMAGINARY(O11)) -> -3.1234058 | R11: =2*LOG10(P11) -> -3.2889335 | S11: =L11*$E$519/P11/$F$519 -> 0.86949113
A12: 11 | B12: 0 | C12: 0 | D12: =AVERAGE(OFFSET(A$2,(ROW(A12)-1)*1.34,,1.34)) -> 15 | E12: =AVERAGE(OFFSET(B$2,(ROW(B12)-1)*1.34,,1.34)) -> 0 | F12: =AVERAGE(OFFSET(C$2,(ROW(C12)-1)*1.34,,1.34)) -> 0 | G12: 0 | H12: 0 | I12: =668.59/A11 -> 66.859 | J12: =1/I12 -> 0.014956849 | K12: -2,329812-8,502764i | L12: =2*IMABS(K12)/512 -> 0.034438201 | M12: =ATAN2(IMREAL(K12),IMAGINARY(K12)) -> -1.8382386 | N12: =2*LOG10(L12) -> -2.9259191 | O12: -1,027994-2,687901i | P12: =2*IMABS(O12)/512 -> 0.011241305 | Q12: =ATAN2(IMREAL(O12),IMAGINARY(O12)) -> -1.9360845 | R12: =2*LOG10(P12) -> -3.8983665 | S12: =L12*$E$519/P12/$F$519 -> 2.5668459
A13: 12 | B13: 0 | C13: 0 | D13: =AVERAGE(OFFSET(A$2,(ROW(A13)-1)*1.34,,1.34)) -> 17 | E13: =AVERAGE(OFFSET(B$2,(ROW(B13)-1)*1.34,,1.34)) -> 0 | F13: =AVERAGE(OFFSET(C$2,(ROW(C13)-1)*1.34,,1.34)) -> 0 | G13: 0 | H13: 0 | I13: =668.59/A12 -> 60.780909 | J13: =1/I13 -> 0.016452534 | K13: 2,631942-1,282586i | L13: =2*IMABS(K13)/512 -> 0.011436807 | M13: =ATAN2(IMREAL(K13),IMAGINARY(K13)) -> -0.45344857 | N13: =2*LOG10(L13) -> -3.8833904 | O13: 3,087510-2,103673i | P13: =2*IMABS(O13)/512 -> 0.014593992 | Q13: =ATAN2(IMREAL(O13),IMAGINARY(O13)) -> -0.59809879 | R13: =2*LOG10(P13) -> -3.6716518 | S13: =L13*$E$519/P13/$F$519 -> 0.65660892
A14: 13 | B14: 0 | C14: 0 | D14: =AVERAGE(OFFSET(A$2,(ROW(A14)-1)*1.34,,1.34)) -> 18 | E14: =AVERAGE(OFFSET(B$2,(ROW(B14)-1)*1.34,,1.34)) -> 0 | F14: =AVERAGE(OFFSET(C$2,(ROW(C14)-1)*1.34,,1.34)) -> 0 | G14: 0 | H14: 0 | I14: =668.59/A13 -> 55.715833 | J14: =1/I14 -> 0.017948219 | K14: 6,388310+5,435344i | L14: =2*IMABS(K14)/512 -> 0.032764443 | M14: =ATAN2(IMREAL(K14),IMAGINARY(K14)) -> 0.70497375 | N14: =2*LOG10(L14) -> -2.9691944 | O14: 4,092962+3,616992i | P14: =2*IMABS(O14)/512 -> 0.021336483 | Q14: =ATAN2(IMREAL(O14),IMAGINARY(O14)) -> 0.72374193 | R14: =2*LOG10(P14) -> -3.3417543
A15: 14 | B15: 0 | C15: 0 | D15: =AVERAGE(OFFSET(A$2,(ROW(A15)-1)*1.34,,1.34)) -> 19 | E15: =AVERAGE(OFFSET(B$2,(ROW(B15)-1)*1.34,,1.34)) -> 0 | F15: =AVERAGE(OFFSET(C$2,(ROW(C15)-1)*1.34,,1.34)) -> 0 | G15: 0 | H15: 0 | I15: =668.59/A14 -> 51.43 | J15: =1/I15 -> 0.019443904 | K15: 3,720827+2,437486i | L15: =2*IMABS(K15)/512 -> 0.017375521 | M15: =ATAN2(IMREAL(K15),IMAGINARY(K15)) -> 0.57994689 | N15: =2*LOG10(L15) -> -3.5201243 | O15: 2,958632+0,494487i | P15: =2*IMABS(O15)/512 -> 0.011717461 | Q15: =ATAN2(IMREAL(O15),IMAGINARY(O15)) -> 0.16560302 | R15: =2*LOG10(P15) -> -3.8623329
A16: 15 | B16: 0 | C16: 0 | D16: =AVERAGE(OFFSET(A$2,(ROW(A16)-1)*1.34,,1.34)) -> 21 | E16: =AVERAGE(OFFSET(B$2,(ROW(B16)-1)*1.34,,1.34)) -> 0 | F16: =AVERAGE(OFFSET(C$2,(ROW(C16)-1)*1.34,,1.34)) -> 0 | G16: 0 | H16: 0 | I16: =668.59/A15 -> 47.756429 | J16: =1/I16 -> 0.020939589 | K16: -0,572324-0,638130i | L16: =2*IMABS(K16)/512 -> 0.0033483756 | M16: =ATAN2(IMREAL(K16),IMAGINARY(K16)) -> -2.3018832 | N16: =2*LOG10(L16) -> -4.9503317 | O16: 3,320231+1,663904i | P16: =2*IMABS(O16)/512 -> 0.014507136 | Q16: =ATAN2(IMREAL(O16),IMAGINARY(O16)) -> 0.46456002 | R16: =2*LOG10(P16) -> -3.6768366
A17: 16 | B17: 0 | C17: 0 | D17: =AVERAGE(OFFSET(A$2,(ROW(A17)-1)*1.34,,1.34)) -> 22 | E17: =AVERAGE(OFFSET(B$2,(ROW(B17)-1)*1.34,,1.34)) -> 0 | F17: =AVERAGE(OFFSET(C$2,(ROW(C17)-1)*1.34,,1.34)) -> 0 | G17: 0 | H17: 0 | I17: =668.59/A16 -> 44.572667 | J17: =1/I17 -> 0.022435274 | K17: -2,344132+1,205234i | L17: =2*IMABS(K17)/512 -> 0.010296169 | M17: =ATAN2(IMREAL(K17),IMAGINARY(K17)) -> 2.6666897 | N17: =2*LOG10(L17) -> -3.9746486 | O17: -4,811169+1,433609i | P17: =2*IMABS(O17)/512 -> 0.019610224 | Q17: =ATAN2(IMREAL(O17),IMAGINARY(O17)) -> 2.8519945 | R17: =2*LOG10(P17) -> -3.4150349
A18: 17 | B18: 0 | C18: 0 | D18: =AVERAGE(OFFSET(A$2,(ROW(A18)-1)*1.34,,1.34)) -> 23 | E18: =AVERAGE(OFFSET(B$2,(ROW(B18)-1)*1.34,,1.34)) -> 0 | F18: =AVERAGE(OFFSET(C$2,(ROW(C18)-1)*1.34,,1.34)) -> 0 | G18: 0 | H18: 0 | I18: =668.59/A17 -> 41.786875 | J18: =1/I18 -> 0.023930959 | K18: -3,883386-2,053953i | L18: =2*IMABS(K18)/512 -> 0.017160583 | M18: =ATAN2(IMREAL(K18),IMAGINARY(K18)) -> -2.6550872 | N18: =2*LOG10(L18) -> -3.5309359 | O18: -4,757354-2,186235i | P18: =2*IMABS(O18)/512 -> 0.020451761 | Q18: =ATAN2(IMREAL(O18),IMAGINARY(O18)) -> -2.7108266 | R18: =2*LOG10(P18) -> -3.3785386
A19: 18 | B19: 0 | C19: 0 | D19: =AVERAGE(OFFSET(A$2,(ROW(A19)-1)*1.34,,1.34)) -> 25 | E19: =AVERAGE(OFFSET(B$2,(ROW(B19)-1)*1.34,,1.34)) -> 0 | F19: =AVERAGE(OFFSET(C$2,(ROW(C19)-1)*1.34,,1.34)) -> 0 | G19: 0 | H19: 0 | I19: =668.59/A18 -> 39.328824 | J19: =1/I19 -> 0.025426644 | K19: -4,146946-2,888152i | L19: =2*IMABS(K19)/512 -> 0.019740513 | M19: =ATAN2(IMREAL(K19),IMAGINARY(K19)) -> -2.5332514 | N19: =2*LOG10(L19) -> -3.4092831 | O19: -2,200850-3,782608i | P19: =2*IMABS(O19)/512 -> 0.01709486 | Q19: =ATAN2(IMREAL(O19),IMAGINARY(O19)) -> -2.0977514 | R19: =2*LOG10(P19) -> -3.5342689
A20: 19 | B20: 0 | C20: 0 | D20: =AVERAGE(OFFSET(A$2,(ROW(A20)-1)*1.34,,1.34)) -> 26 | E20: =AVERAGE(OFFSET(B$2,(ROW(B20)-1)*1.34,,1.34)) -> 0 | F20: =AVERAGE(OFFSET(C$2,(ROW(C20)-1)*1.34,,1.34)) -> 0 | G20: 0 | H20: 0 | I20: =668.59/A19 -> 37.143889 | J20: =1/I20 -> 0.026922329 | K20: 1,415720-0,314341i | L20: =2*IMABS(K20)/512 -> 0.0056648348 | M20: =ATAN2(IMREAL(K20),IMAGINARY(K20)) -> -0.21849161 | N20: =2*LOG10(L20) -> -4.4936255 | O20: 2,035679-0,584132i | P20: =2*IMABS(O20)/512 -> 0.0082727691 | Q20: =ATAN2(IMREAL(O20),IMAGINARY(O20)) -> -0.27943897 | R20: =2*LOG10(P20) -> -4.1646982
A21: 20 | B21: 0 | C21: 0 | D21: =AVERAGE(OFFSET(A$2,(ROW(A21)-1)*1.34,,1.34)) -> 27 | E21: =AVERAGE(OFFSET(B$2,(ROW(B21)-1)*1.34,,1.34)) -> 0 | F21: =AVERAGE(OFFSET(C$2,(ROW(C21)-1)*1.34,,1.34)) -> 0 | G21: 0 | H21: 0 | I21: =668.59/A20 -> 35.188947 | J21: =1/I21 -> 0.028418014 | K21: 5,628709+1,183069i | L21: =2*IMABS(K21)/512 -> 0.022467566 | M21: =ATAN2(IMREAL(K21),IMAGINARY(K21)) -> 0.20716917 | N21: =2*LOG10(L21) -> -3.2968879 | O21: 3,748365+2,227896i | P21: =2*IMABS(O21)/512 -> 0.017033114 | Q21: =ATAN2(IMREAL(O21),IMAGINARY(O21)) -> 0.53626563 | R21: =2*LOG10(P21) -> -3.5374119
A22: 21 | B22: 0 | C22: 0 | D22: =AVERAGE(OFFSET(A$2,(ROW(A22)-1)*1.34,,1.34)) -> 29 | E22: =AVERAGE(OFFSET(B$2,(ROW(B22)-1)*1.34,,1.34)) -> 0 | F22: =AVERAGE(OFFSET(C$2,(ROW(C22)-1)*1.34,,1.34)) -> 0 | G22: 0 | H22: 0 | I22: =668.59/A21 -> 33.4295 | J22: =1/I22 -> 0.029913699 | K22: 3,426447+2,203103i | L22: =2*IMABS(K22)/512 -> 0.015912493 | M22: =ATAN2(IMREAL(K22),IMAGINARY(K22)) -> 0.57141741 | N22: =2*LOG10(L22) -> -3.5965236 | O22: 2,632503+3,234738i | P22: =2*IMABS(O22)/512 -> 0.016291265 | Q22: =ATAN2(IMREAL(O22),IMAGINARY(O22)) -> 0.88768359 | R22: =2*LOG10(P22) -> -3.5760904
A23: 22 | B23: 0 | C23: 0 | D23: =AVERAGE(OFFSET(A$2,(ROW(A23)-1)*1.34,,1.34)) -> 30 | E23: =AVERAGE(OFFSET(B$2,(ROW(B23)-1)*1.34,,1.34)) -> 0 | F23: =AVERAGE(OFFSET(C$2,(ROW(C23)-1)*1.34,,1.34)) -> 0 | G23: 0 | H23: 0 | I23: =668.59/A22 -> 31.837619 | J23: =1/I23 -> 0.031409384 | K23: -1,411107+1,710625i | L23: =2*IMABS(K23)/512 -> 0.0086622455 | M23: =ATAN2(IMREAL(K23),IMAGINARY(K23)) -> 2.2605412 | N23: =2*LOG10(L23) -> -4.124739 | O23: 0,108978-0,305114i | P23: =2*IMABS(O23)/512 -> 0.0012655934 | Q23: =ATAN2(IMREAL(O23),IMAGINARY(O23)) -> -1.2277471 | R23: =2*LOG10(P23) -> -5.7954116
A24: 23 | B24: 0 | C24: 0 | D24: =AVERAGE(OFFSET(A$2,(ROW(A24)-1)*1.34,,1.34)) -> 31 | E24: =AVERAGE(OFFSET(B$2,(ROW(B24)-1)*1.34,,1.34)) -> 0 | F24: =AVERAGE(OFFSET(C$2,(ROW(C24)-1)*1.34,,1.34)) -> 0 | G24: 0 | H24: 0 | I24: =668.59/A23 -> 30.390455 | J24: =1/I24 -> 0.032905069 | K24: -2,319059-0,465410i | L24: =2*IMABS(K24)/512 -> 0.0092394507 | M24: =ATAN2(IMREAL(K24),IMAGINARY(K24)) -> -2.9435345 | N24: =2*LOG10(L24) -> -4.0687077 | O24: -2,079424-0,138794i | P24: =2*IMABS(O24)/512 -> 0.0081408236 | Q24: =ATAN2(IMREAL(O24),IMAGINARY(O24)) -> -3.0749451 | R24: =2*LOG10(P24) -> -4.1786633
A25: 24 | B25: 0 | C25: 0 | D25: =AVERAGE(OFFSET(A$2,(ROW(A25)-1)*1.34,,1.34)) -> 33 | E25: =AVERAGE(OFFSET(B$2,(ROW(B25)-1)*1.34,,1.34)) -> 0 | F25: =AVERAGE(OFFSET(C$2,(ROW(C25)-1)*1.34,,1.34)) -> 0 | G25: 0 | H25: 0 | I25: =668.59/A24 -> 29.06913 | J25: =1/I25 -> 0.034400754 | K25: -3,548025-1,606907i | L25: =2*IMABS(K25)/512 -> 0.015214646 | M25: =ATAN2(IMREAL(K25),IMAGINARY(K25)) -> -2.7163282 | N25: =2*LOG10(L25) -> -3.6354763 | O25: -3,351515-1,564718i | P25: =2*IMABS(O25)/512 -> 0.014448371 | Q25: =ATAN2(IMREAL(O25),IMAGINARY(O25)) -> -2.7047995 | R25: =2*LOG10(P25) -> -3.6803622
... A72: 71 | B72: 0 | C72: 0 | D72: =AVERAGE(OFFSET(A$2,(ROW(A72)-1)*1.34,,1.34)) -> 96 | E72: =AVERAGE(OFFSET(B$2,(ROW(B72)-1)*1.34,,1.34)) -> 0 | F72: =AVERAGE(OFFSET(C$2,(ROW(C72)-1)*1.34,,1.34)) -> 0 | G72: 0 | H72: 0 | I72: =668.59/A71 -> 9.5512857 | J72: =1/I72 -> 0.10469795 | K72: -0,307425+0,877493i | L72: =2*IMABS(K72)/512 -> 0.003631981 | M72: =ATAN2(IMREAL(K72),IMAGINARY(K72)) -> 1.9077782 | N72: =2*LOG10(L72) -> -4.8797129 | O72: -0,626167+0,256645i | P72: =2*IMABS(O72)/512 -> 0.0026434427 | Q72: =ATAN2(IMREAL(O72),IMAGINARY(O72)) -> 2.7526095 | R72: =2*LOG10(P72) -> -5.1556602
A73: 72 | B73: 0 | C73: 0 | D73: =AVERAGE(OFFSET(A$2,(ROW(A73)-1)*1.34,,1.34)) -> 97 | E73: =AVERAGE(OFFSET(B$2,(ROW(B116)-1)*1.34,,1.34)) -> 220.11 | F73: =AVERAGE(OFFSET(C$2,(ROW(C116)-1)*1.34,,1.34)) -> 234.661 | G73: =(E73-$E$515)/$E$519 -> 0.33565021 | H73: =(F73-$F$515)/$F$519 -> 0.34441993 | I73: =668.59/A72 -> 9.4167606 | J73: =1/I73 -> 0.10619363 | K73: -0,493042-0,787331i | L73: =2*IMABS(K73)/512 -> 0.0036287791 | M73: =ATAN2(IMREAL(K73),IMAGINARY(K73)) -> -2.1302721 | N73: =2*LOG10(L73) -> -4.8804789 | O73: 0,054066-0,501293i | P73: =2*IMABS(O73)/512 -> 0.0019695319 | Q73: =ATAN2(IMREAL(O73),IMAGINARY(O73)) -> -1.4633585 | R73: =2*LOG10(P73) -> -5.411274
A74: 73 | B74: 0 | C74: 0 | D74: =AVERAGE(OFFSET(A$2,(ROW(A74)-1)*1.34,,1.34)) -> 98 | E74: =AVERAGE(OFFSET(B$2,(ROW(B117)-1)*1.34,,1.34)) -> 220.081 | F74: =AVERAGE(OFFSET(C$2,(ROW(C117)-1)*1.34,,1.34)) -> 234.5975 | G74: =(E74-$E$515)/$E$519 -> 0.3318599 | H74: =(F74-$F$515)/$F$519 -> 0.33746606 | I74: =668.59/A73 -> 9.2859722 | J74: =1/I74 -> 0.10768932 | K74: 0,097287-1,471815i | L74: =2*IMABS(K74)/512 -> 0.0057618236 | M74: =ATAN2(IMREAL(K74),IMAGINARY(K74)) -> -1.5047923 | N74: =2*LOG10(L74) -> -4.4788801 | O74: 0,038871-0,649703i | P74: =2*IMABS(O74)/512 -> 0.0025424405 | Q74: =ATAN2(IMREAL(O74),IMAGINARY(O74)) -> -1.5110387 | R74: =2*LOG10(P74) -> -5.1894984
A75: 74 | B75: 0 | C75: 0 | D75: =AVERAGE(OFFSET(A$2,(ROW(A75)-1)*1.34,,1.34)) -> 100 | E75: =AVERAGE(OFFSET(B$2,(ROW(B118)-1)*1.34,,1.34)) -> 220.065 | F75: =AVERAGE(OFFSET(C$2,(ROW(C118)-1)*1.34,,1.34)) -> 234.565 | G75: =(E75-$E$515)/$E$519 -> 0.32976869 | H75: =(F75-$F$515)/$F$519 -> 0.33390699 | I75: =668.59/A74 -> 9.1587671 | J75: =1/I75 -> 0.109185 | K75: 0,430954-0,569239i | L75: =2*IMABS(K75)/512 -> 0.0027889487 | M75: =ATAN2(IMREAL(K75),IMAGINARY(K75)) -> -0.92278549 | N75: =2*LOG10(L75) -> -5.109119 | O75: 0,193017-1,236245i | P75: =2*IMABS(O75)/512 -> 0.0048875871 | Q75: =ATAN2(IMREAL(O75),IMAGINARY(O75)) -> -1.4159151 | R75: =2*LOG10(P75) -> -4.621811
A76: 75 | B76: 0 | C76: 0 | D76: =AVERAGE(OFFSET(A$2,(ROW(A76)-1)*1.34,,1.34)) -> 101 | E76: =AVERAGE(OFFSET(B$2,(ROW(B119)-1)*1.34,,1.34)) -> 220.034 | F76: =AVERAGE(OFFSET(C$2,(ROW(C119)-1)*1.34,,1.34)) -> 234.4995 | G76: =(E76-$E$515)/$E$519 -> 0.32571698 | H76: =(F76-$F$515)/$F$519 -> 0.3267341 | I76: =668.59/A75 -> 9.035 | J76: =1/I76 -> 0.11068069 | K76: 0,514194+0,077340i | L76: =2*IMABS(K76)/512 -> 0.0020311634 | M76: =ATAN2(IMREAL(K76),IMAGINARY(K76)) -> 0.14929105 | N76: =2*LOG10(L76) -> -5.3845103 | O76: 0,624862-0,057164i | P76: =2*IMABS(O76)/512 -> 0.0024510598 | Q76: =ATAN2(IMREAL(O76),IMAGINARY(O76)) -> -0.091228665 | R76: =2*LOG10(P76) -> -5.2212922
A77: 76 | B77: 0 | C77: 0 | D77: =AVERAGE(OFFSET(A$2,(ROW(A77)-1)*1.34,,1.34)) -> 102 | E77: =AVERAGE(OFFSET(B$2,(ROW(B120)-1)*1.34,,1.34)) -> 220.018 | F77: =AVERAGE(OFFSET(C$2,(ROW(C120)-1)*1.34,,1.34)) -> 234.467 | G77: =(E77-$E$515)/$E$519 -> 0.32362578 | H77: =(F77-$F$515)/$F$519 -> 0.32317504 | I77: =668.59/A76 -> 8.9145333 | J77: =1/I77 -> 0.11217637 | K77: 0,062761+0,838191i | L77: =2*IMABS(K77)/512 -> 0.0032833492 | M77: =ATAN2(IMREAL(K77),IMAGINARY(K77)) -> 1.4960591 | N77: =2*LOG10(L77) -> -4.9673659 | O77: -0,133118+0,980640i | P77: =2*IMABS(O77)/512 -> 0.0038657573 | Q77: =ATAN2(IMREAL(O77),IMAGINARY(O77)) -> 1.7057177 | R77: =2*LOG10(P77) -> -4.8255308
A78: 77 | B78: 0 | C78: 0 | D78: =AVERAGE(OFFSET(A$2,(ROW(A78)-1)*1.34,,1.34)) -> 104 | E78: =AVERAGE(OFFSET(B$2,(ROW(B121)-1)*1.34,,1.34)) -> 220.003 | F78: =AVERAGE(OFFSET(C$2,(ROW(C121)-1)*1.34,,1.34)) -> 234.4345 | G78: =(E78-$E$515)/$E$519 -> 0.32166527 | H78: =(F78-$F$515)/$F$519 -> 0.31961597 | I78: =668.59/A77 -> 8.7972368 | J78: =1/I78 -> 0.11367206 | K78: -0,491393+0,826896i | L78: =2*IMABS(K78)/512 -> 0.003757366 | M78: =ATAN2(IMREAL(K78),IMAGINARY(K78)) -> 2.1069861 | N78: =2*LOG10(L78) -> -4.850233 | O78: -0,321800+0,693550i | P78: =2*IMABS(O78)/512 -> 0.0029866004 | Q78: =ATAN2(IMREAL(O78),IMAGINARY(O78)) -> 2.0052229 | R78: =2*LOG10(P78) -> -5.0496458
A79: 78 | B79: 0 | C79: 0 | D79: =AVERAGE(OFFSET(A$2,(ROW(A79)-1)*1.34,,1.34)) -> 105 | E79: =AVERAGE(OFFSET(B$2,(ROW(B122)-1)*1.34,,1.34)) -> 219.971 | F79: =AVERAGE(OFFSET(C$2,(ROW(C122)-1)*1.34,,1.34)) -> 234.369 | G79: =(E79-$E$515)/$E$519 -> 0.31748286 | H79: =(F79-$F$515)/$F$519 -> 0.31244308 | I79: =668.59/A78 -> 8.682987 | J79: =1/I79 -> 0.11516774 | K79: -0,305065+0,441812i | L79: =2*IMABS(K79)/512 -> 0.0020972689 | M79: =ATAN2(IMREAL(K79),IMAGINARY(K79)) -> 2.1751085 | N79: =2*LOG10(L79) -> -5.3566918 | O79: -0,264353+0,827558i | P79: =2*IMABS(O79)/512 -> 0.0033935731 | Q79: =ATAN2(IMREAL(O79),IMAGINARY(O79)) -> 1.8799889 | R79: =2*LOG10(P79) -> -4.9386856
A80: 79 | B80: 0 | C80: 0 | D80: =AVERAGE(OFFSET(A$2,(ROW(A80)-1)*1.34,,1.34)) -> 106 | E80: =AVERAGE(OFFSET(B$2,(ROW(B123)-1)*1.34,,1.34)) -> 219.955 | F80: =AVERAGE(OFFSET(C$2,(ROW(C123)-1)*1.34,,1.34)) -> 234.336 | G80: =(E80-$E$515)/$E$519 -> 0.31539166 | H80: =(F80-$F$515)/$F$519 -> 0.30882926 | I80: =668.59/A79 -> 8.5716667 | J80: =1/I80 -> 0.11666343 | K80: -0,390362-0,227212i | L80: =2*IMABS(K80)/512 -> 0.0017643446 | M80: =ATAN2(IMREAL(K80),IMAGINARY(K80)) -> -2.6144728 | N80: =2*LOG10(L80) -> -5.5068332 | O80: -0,568245-0,311688i | P80: =2*IMABS(O80)/512 -> 0.0025316954 | Q80: =ATAN2(IMREAL(O80),IMAGINARY(O80)) -> -2.6398942 | R80: =2*LOG10(P80) -> -5.1931771
A81: 80 | B81: 0 | C81: 0 | D81: =AVERAGE(OFFSET(A$2,(ROW(A81)-1)*1.34,,1.34)) -> 108 | E81: =AVERAGE(OFFSET(B$2,(ROW(B124)-1)*1.34,,1.34)) -> 219.94 | F81: =AVERAGE(OFFSET(C$2,(ROW(C124)-1)*1.34,,1.34)) -> 234.3035 | G81: =(E81-$E$515)/$E$519 -> 0.31343115 | H81: =(F81-$F$515)/$F$519 -> 0.30527019 | I81: =668.59/A80 -> 8.4631646 | J81: =1/I81 -> 0.11815911 | K81: 0,130756-0,928477i | L81: =2*IMABS(K81)/512 -> 0.0036626519 | M81: =ATAN2(IMREAL(K81),IMAGINARY(K81)) -> -1.4308879 | N81: =2*LOG10(L81) -> -4.8724087 | O81: 0,456220-1,374274i | P81: =2*IMABS(O81)/512 -> 0.0056563332 | Q81: =ATAN2(IMREAL(O81),IMAGINARY(O81)) -> -1.2502718 | R81: =2*LOG10(P81) -> -4.49493
A82: 81 | B82: 0 | C82: 0 | D82: =AVERAGE(OFFSET(A$2,(ROW(A82)-1)*1.34,,1.34)) -> 109 | E82: =AVERAGE(OFFSET(B$2,(ROW(B125)-1)*1.34,,1.34)) -> 219.908 | F82: =AVERAGE(OFFSET(C$2,(ROW(C125)-1)*1.34,,1.34)) -> 234.2385 | G82: =(E82-$E$515)/$E$519 -> 0.30924874 | H82: =(F82-$F$515)/$F$519 -> 0.29815206 | I82: =668.59/A81 -> 8.357375 | J82: =1/I82 -> 0.1196548 | K82: 0,704123-0,740050i | L82: =2*IMABS(K82)/512 -> 0.0039902362 | M82: =ATAN2(IMREAL(K82),IMAGINARY(K82)) -> -0.81027025 | N82: =2*LOG10(L82) -> -4.7980028 | O82: 0,627877-0,406763i | P82: =2*IMABS(O82)/512 -> 0.0029223493 | Q82: =ATAN2(IMREAL(O82),IMAGINARY(O82)) -> -0.57485433 | R82: =2*LOG10(P82) -> -5.0685357
A83: 82 | B83: 0 | C83: 0 | D83: =AVERAGE(OFFSET(A$2,(ROW(A83)-1)*1.34,,1.34)) -> 110 | E83: =AVERAGE(OFFSET(B$2,(ROW(B126)-1)*1.34,,1.34)) -> 219.893 | F83: =AVERAGE(OFFSET(C$2,(ROW(C126)-1)*1.34,,1.34)) -> 234.206 | G83: =(E83-$E$515)/$E$519 -> 0.30728824 | H83: =(F83-$F$515)/$F$519 -> 0.29459299 | I83: =668.59/A82 -> 8.2541975 | J83: =1/I83 -> 0.12115048 | K83: 0,428978-0,332420i | L83: =2*IMABS(K83)/512 -> 0.0021199287 | M83: =ATAN2(IMREAL(K83),IMAGINARY(K83)) -> -0.6592548 | N83: =2*LOG10(L83) -> -5.3473575 | O83: 0,032032-0,236823i | P83: =2*IMABS(O83)/512 -> 0.00093351352 | Q83: =ATAN2(IMREAL(O83),IMAGINARY(O83)) -> -1.4363551 | R83: =2*LOG10(P83) -> -6.0597588
A84: 83 | B84: 0 | C84: 0 | D84: =AVERAGE(OFFSET(A$2,(ROW(A84)-1)*1.34,,1.34)) -> 112 | E84: =AVERAGE(OFFSET(B$2,(ROW(B127)-1)*1.34,,1.34)) -> 219.877 | F84: =AVERAGE(OFFSET(C$2,(ROW(C127)-1)*1.34,,1.34)) -> 234.173 | G84: =(E84-$E$515)/$E$519 -> 0.30519703 | H84: =(F84-$F$515)/$F$519 -> 0.29097917 | I84: =668.59/A83 -> 8.1535366 | J84: =1/I84 -> 0.12264617 | K84: -0,002832+0,653024i | L84: =2*IMABS(K84)/512 -> 0.002550899 | M84: =ATAN2(IMREAL(K84),IMAGINARY(K84)) -> 1.575133 | N84: =2*LOG10(L84) -> -5.1866135 | O84: 0,368642+0,572028i | P84: =2*IMABS(O84)/512 -> 0.002658297 | Q84: =ATAN2(IMREAL(O84),IMAGINARY(O84)) -> 0.99833437 | R84: =2*LOG10(P84) -> -5.150793
... A257: 256 | B257: 215.784 | C257: 228.524 | D257: =AVERAGE(OFFSET(A$2,(ROW(A257)-1)*1.34,,1.34)) -> 344 | E257: =AVERAGE(OFFSET(B$2,(ROW(B300)-1)*1.34,,1.34)) -> 212.595 | F257: =AVERAGE(OFFSET(C$2,(ROW(C300)-1)*1.34,,1.34)) -> 226.129 | G257: =(E257-$E$515)/$E$519 -> -0.64656279 | H257: =(F257-$F$515)/$F$519 -> -0.5899172 | I257: =668.59/A256 -> 2.6219216 | J257: =1/I257 -> 0.38139966 | K257: -0,368661+0,175429i | L257: =2*IMABS(K257)/512 -> 0.0015948137 | M257: =ATAN2(IMREAL(K257),IMAGINARY(K257)) -> 2.6974473 | N257: =2*LOG10(L257) -> -5.5945801 | O257: -0,429503-0,013748i | P257: =2*IMABS(O257)/512 -> 0.0016786054 | Q257: =ATAN2(IMREAL(O257),IMAGINARY(O257)) -> -3.1095945 | R257: =2*LOG10(P257) -> -5.5501028
A258: 257 | B258: 215.753 | C258: 228.486 | D258: =AVERAGE(OFFSET(A$2,(ROW(A258)-1)*1.34,,1.34)) -> 345 | E258: =AVERAGE(OFFSET(B$2,(ROW(B301)-1)*1.34,,1.34)) -> 212.691 | F258: =AVERAGE(OFFSET(C$2,(ROW(C301)-1)*1.34,,1.34)) -> 226.293 | G258: =(E258-$E$515)/$E$519 -> -0.63401556 | H258: =(F258-$F$515)/$F$519 -> -0.5719576 | I258: =668.59/A257 -> 2.6116797 | J258: =1/I258 -> 0.38289535 | K258: -0.61182 | L258: =2*IMABS(K258)/512 -> 0.0023899219 | M258: =ATAN2(IMREAL(K258),IMAGINARY(K258)) -> 3.1415927 | O258: -0,331443 | P258: =2*IMABS(O258)/512 -> 0.0012946992 | Q258: =ATAN2(IMREAL(O258),IMAGINARY(O258)) -> 3.1415927 | R258: =2*LOG10(P258) -> -5.7756622
...

Sheet Thermal Diffusivity
B1: Value | C1: Abs Uncertainty | D1: Rel Uncertainty
A2: diurnal period [s] | B2: =24*3699 -> 88776
A3: annual period [s] | B3: =668.59*B2 -> 59354746
A4: l | B4: 0.4 | C4: 0.01 | D4: =C4/B4 -> 0.025
A5: i [°] | B5: 30 | C5: 2 | D5: =C5/B5 -> 0.066666667
A6: i[rad] | B6: =PI()/6 -> 0.52359878 | C6: =PI()/180 -> 0.017453293 | D6: =C6/B6 -> 0.033333333
A7: z_0 [m] | B7: 0.0102 | C7: =D7*B7 -> 0.0010965 | D7: =0.1075 -> 0.1075
A8: l' [m] | B8: =0.4*COS(B6) -> 0.34641016 | C8: =SQRT((D4)^2+(B6*TAN(B6)*D6)^2)*B8 -> 0.0093372746 | D8: =C8/B8 -> 0.02695439
A9: z_0/l' | B9: =B7/B8 -> 0.029444864 | C9: =SQRT((D7)^2+(D8)^2)*B9 -> 0.0032633079 | D9: =C9/B9 -> 0.11082775
A10: Delta Surface Temperature [K] | B10: ='2nd year FFT'!F518 -> 16.241 | C10: 1 | D10: =C10/B10 -> 0.061572563
A11: Delta Mole Temperature [K] | B11: ='2nd year FFT'!E518 -> 13.208 | C11: 1 | D11: =C11/B11 -> 0.07571169
A12: Chi (fund. mode) | B12: ='2nd year FFT'!S3 -> 0.72406983
A13: ln Chi | B13: =LN(B12) -> -0.32286745
A14: SQRT(2)/2 | B14: =SQRT(2)/2 -> 0.70710678
A16: Thermal diffusivity from z_0 and Phase delay annual wave
C17: abs uncertainty | D17: rel unc. | E17: x | F17: tan Phi_a | G17: F_Phi(x)
A18: Phi_a | B18: ='2nd year FFT'!T4 -> 0.19638435 | C18: =2*PI()/512 -> 0.012271846 | D18: =C18/B18 -> 0.062488921 | E18: 0.41842642 | F18: =TAN(B18) -> 0.19894856 | G18: =F18-(B14-EXP(- E18)*SIN(E18+PI()/4))/(B14-EXP(-E18)*COS(E18+PI()/4)) -> 0.0018300205
A19: Phi_a [sol] | B19: =B18*668.59/2/PI() -> 20.897142 | C19: =C18/2/PI()*668.59 -> 1.3058398 | D19: d_a | E19: =B8/E18*100 -> 82.788787 | F19: cm
D20: d_d | E20: 3.4389133 | F20: cm
D21: Kappa | E21: =E19^2*PI()/B3/10^4 -> 3.627751e-08 | F21: m^2/s
D22: Delta Kappa | E22: =E21*G28 -> 5.321472e-09 | F22: m^2/s
D23: Delta d_a | E23: =E19*F28 -> 6.072057 | F23: cm
D24: Lambda | E24: =2*PI()*E19 -> 520.17729 | F24: cm
B26: Error analysis
B27: F1(x) | C27: dF1/dx | D27: dF1/dPhi | E27: Delta x/x | F27: Delta delta/delta | G27: Delta Kappa/Kappa
B28: =(EXP(E18)/SQRT(2)-SIN(E18+PI()/4))/(EXP(E18)/SQRT(2)-COS(E18+PI()/4)) -> 0.19711854 | C28: =2*(1-EXP(E18)*(COS(E18)-SIN(E18)))/(EXP(E18)-COS(E18)+SIN(E18))^2 -> 0.44698394 | D28: =(1/COS(B18))^2 -> 1.0395805 | E28: =D28/C28/E18*C18 -> 0.06821141 | F28: =SQRT(E28^2+D8^2) -> 0.073343954 | G28: =F28*2 -> 0.14668791
A31: Thermal diffusivity from z_0 and amplitude ratio annual wave
C32: Delta Chi_a/Chi_a | E32: x | F32: C | G32: F_Chi(x)
A33: Chi_a | B33: =B11/B10 -> 0.81325042 | C33: =SQRT((C10/B10)^2+(C11/B11)^2)*B33 -> 0.079363577 | E33: 0.41351362 | F33: =1+EXP(-2*E33)-2*EXP(-E33)*COS(E33) -> 0.22618209 | G33: =LN(B33)-LN(B14)+LN(E33)-0.5*LN(F33) -> -4.3581783e-10
A34: ln Chi_a | B34: =LN(B33) -> -0.2067162 | D34: d_a | E34: =B8/E33*100 -> 83.77237 | F34: cm
D35: d_d | E35: =E20 -> 3.4389133 | F35: cm
D36: Kappa | E36: =E34^2*PI()/B3/10^4 -> 3.714463e-08 | F36: m^2/s
D37: Delta Kappa | E37: =E36*G41 -> 2.8608507e-08 | F37: m^2/s
B39: Error analysis
B40: F2(x) | C40: dF2/dx | D40: Delta F2 | E40: Delta x/x | F40: Delta delta/delta | G40: Delta kappa/kappa
B41: =LN(E33)-0.5*LN(1+EXP(-2*E33)-2*EXP(-E33)*COS(E33)) -> -0.13985739 | C41: =1/E33+(1-EXP(E33)*(COS(E33)+SIN(E33)))/(1+EXP(2*E33)-2*EXP(E33)*COS(E33)) -> 0.4996072 | D41: =C33 -> 0.079363577 | E41: =D41/C41/E33 -> 0.38415167 | F41: =SQRT(E41^2+D8^2) -> 0.38509614 | G41: =F41*2 -> 0.77019229
